Workbook
Name Slicer_Channel: #N/A
Name Slicer_Country: #N/A
Name Slicer_Month_OD: #N/A
Name Slicer_ProductCategory: #N/A
Name Slicer_Region: #N/A
Name Slicer_Region1: #N/A
Name Slicer_Salesperson: #N/A

Sheet Data- Original
A1: OrderID | B1: OrderDate | C1: RequiredDate | D1: Region | E1: Country | F1: City | G1: CustomerSegment | H1: Channel | I1: Salesperson | J1: ProductCategory | K1: SKU | L1: UnitCost | M1: UnitPrice | N1: DiscountPct | O1: Quantity
A2: ORD-2024-275203 | B2: 45362 | C2: 45388 | D2: Africa | E2: Kenya | F2: Kisumu | G2: Corporate | H2: Retail | I2: C. Otieno | J2: Components | K2: CMP-8270 | L2: 279.24 | M2: 608.9 | N2: 0.112 | O2: 9
A3: ORD-2024-358795 | B3: 45588 | C3: 45587 | D3: Africa | E3: Nigeria | F3: Port Harcourt | G3: Education | H3: Online | I3: J. Njeri | J3: Printers | K3: PRN-9322 | L3: 1084.39 | M3: 759.33 | N3: 0.237 | O3: 31
A4: ORD-2023-373538 | B4: 44985 | C4: 45010 | D4: Africa | E4: Kenya | F4: Nairobi | G4: Corporate | H4: Retail | I4: I. Johnson | J4: Networking | K4: NET-9666 | L4: 1460.76 | M4: -30.66 | N4: 0.131 | O4: 12
A5: ORD-2025-168148 | B5: 45745 | C5: 45749 | D5: Africa | E5: Nigeria | F5: Lagos | G5: Non-Profit | H5: Marketplace | I5: G. Dubois | J5: Phones | K5: PHN-4556 | L5: 259.93 | M5: 255.94 | N5: 0.072 | O5: 22
A6: ORD-2023-824839 | B6: 45266 | C6: 45291 | D6: Asia | E6: Japan | F6: Osaka | G6: Consumer | H6: Retail | I6: L. Okafor | J6: Printers | K6: PRN-8041 | L6: 663.03 | M6: 813.51 | N6: 0.102 | O6: 15
A7: ORD-2023-723587 | B7: 44928 | C7: 44931 | D7: Americas | E7: Canada | F7: Toronto | G7: Corporate | H7: Distributor | I7: B. Chen | J7: Laptops | K7: LAP-8555 | L7: 315.87 | M7: 591.68 | N7: 0 | O7: 7
A8: ORD-2024-336584 | B8: 45653 | C8: 45671 | D8: Asia | E8: India | F8: Bengaluru | G8: Small Business | H8: Marketplace | I8: E. Garcia | J8: Monitors | K8: MON-8629 | L8: 586.07 | M8: 845.97 | N8: 0.147 | O8: 4
A9: ORD-2023-112666 | B9: 44941 | C9: 44939 | D9: Africa | E9: Nigeria | F9: Abuja | G9: Education | H9: Online | I9: O. Wang | J9: Printers | K9: PRN-6276 | L9: 28.38 | M9: 47.22 | N9: 0.194 | O9: 18
A10: ORD-2024-589570 | B10: 45416 | C10: 45441 | D10: Africa | E10: Nigeria | F10: Abuja | G10: Non-Profit | H10: Marketplace | I10: O. Wang | J10: Monitors | K10: MON-6892 | L10: 1295.34 | M10: 2530.81 | N10: 0.031 | O10: 6
A11: ORD-2025-997421 | B11: 45798 | C11: 45817 | D11: Americas | E11: Brazil | F11: São Paulo | G11: Non-Profit | H11: Online | I11: A. Patel | J11: Components | K11: CMP-3731 | L11: 1331.38 | M11: 2309.56 | N11: 0.149 | O11: 31
A12: ORD-2024-210687 | B12: 45319 | C12: 45331 | D12: Europe | E12: Germany | F12: Berlin | G12: Corporate | H12: Online | I12: G. Dubois | J12: Accessories | K12: ACC-7938 | L12: 644.17 | M12: 700.12 | N12: 0.006 | O12: 23
A13: ORD-2025-515515 | B13: 45660 | C13: 45680 | D13: Asia | E13: Japan | F13: Osaka | G13: Corporate | H13: Distributor | I13: F. Müller | J13: Phones | K13: PHN-7019 | L13: 908.6 | M13: 691.37 | N13: 0.25 | O13: 20
... A34: ORD-2025-474710 | B34: 45862 | C34: 45875 | D34: Africa | E34: South Africa | F34: Johannesburg | G34: Education | H34: Marketplace | I34: D. Smith | J34: Networking | K34: NET-7966 | L34: 1463.9 | M34: 2633.02 | N34: 0.084 | O34: 4
A35: ORD-2024-629525 | B35: 45400 | C35: 45420 | D35: Europe | E35: United Kingdom | F35: London | G35: Non-Profit | I35: D. Smith | J35: Laptops | K35: LAP-9932 | L35: 645.33 | M35: 1321.85 | N35: 0 | O35: 10
A36: ORD-2024-167215 | B36: 45527 | C36: 45525 | D36: Africa | E36: South Africa | F36: Johannesburg | G36: Education | H36: Retail | I36: E. Garcia | J36: Components | K36: CMP-1559 | L36: 1432.52 | M36: 3036.87 | N36: 0 | O36: 9
A37: ORD-2023-864121 | B37: 45012 | C37: 45038 | D37: Asia | E37: India | F37: Delhi | G37: Non-Profit | H37: Marketplace | I37: J. Njeri | J37: Printers | K37: PRN-4506 | L37: 178.53 | M37: 199.37 | N37: 0.101 | O37: 37
A38: ORD-2024-692673 | B38: 45358 | C38: 45376 | D38: Europe | E38: Germany | F38: Munich | G38: Corporate | H38: Online | I38: B. Chen | J38: Components | K38: CMP-7617 | L38: 712.84 | M38: 927.51 | N38: 0.243 | O38: 27
A39: ORD-2025-718992 | B39: 45832 | C39: 45848 | D39: Asia | E39: China | F39: Shanghai | G39: Enterprise | H39: Direct | I39: N. Brown | J39: Components | K39: CMP-8390 | L39: 757.19 | M39: 1735.41 | N39: 0.136 | O39: 8
A40: ORD-2024-599522 | B40: 45401 | C40: 45418 | D40: Africa | E40: Nigeria | F40: Port Harcourt | G40: Non-Profit | H40: Online | I40: A. Patel | J40: Printers | K40: PRN-7303 | L40: 865.33 | M40: 1395.64 | N40: 0.175 | O40: 13
A41: ORD-2023-651638 | B41: 45094 | C41: 45101 | D41: Americas | E41: USA | F41: San Francisco | G41: Corporate | H41: Retail | I41: I. Johnson | J41: Printers | K41: PRN-6536 | L41: 313.99 | M41: 454.42 | N41: 0.129 | O41: 9
A42: ORD-2024-635626 | B42: 45531 | C42: 45554 | D42: Europe | E42: Germany | F42: Berlin | G42: Small Business | H42: Direct | I42: D. Smith | J42: Monitors | K42: MON-9967 | L42: 1024.01 | M42: 1580.97 | N42: 0.037 | O42: 27
A43: ORD-2024-296582 | B43: 45302 | C43: 45324 | D43: Africa | E43: South Africa | F43: Durban | G43: Consumer | H43: Online | I43: K. Singh | J43: Networking | K43: NET-1412 | L43: 1206.2 | M43: 1759.79 | N43: 0 | O43: 6
A44: ORD-2024-998320 | B44: 45590 | C44: 45610 | D44: Africa | E44: Kenya | F44: Mombasa | G44: Corporate | H44: Direct | I44: H. Kim | J44: Printers | K44: PRN-3143 | L44: 1396.48 | M44: 3204.5 | N44: 0.318 | O44: 14
A45: ORD-2025-820255 | B45: 45806 | C45: 45828 | D45: Europe | E45: Germany | F45: Berlin | G45: Corporate | H45: Direct | I45: A. Patel | J45: Printers | K45: PRN-9787 | L45: 483.47 | M45: 1135.43 | N45: 0.146 | O45: 11
A46: ORD-2024-389336 | B46: 45432 | C46: 45445 | D46: Americas | E46: Canada | F46: Vancouver | G46: Enterprise | H46: Marketplace | I46: K. Singh | J46: Components | K46: CMP-5946 | L46: 675.43 | M46: 996.36 | N46: 0.182 | O46: 22
A47: ORD-2023-308124 | B47: 45035 | C47: 45046 | D47: Asia | E47: India | F47: Delhi | G47: Small Business | H47: Retail | I47: A. Patel | J47: Networking | K47: NET-2062 | L47: 826.55 | M47: 1397.05 | N47: 0.169 | O47: 28
... A77: ORD-2023-722117 | B77: 45187 | C77: 45207 | D77: Asia | E77: India | F77: Delhi | G77: Small Business | H77: Direct | I77: B. Chen | J77: Components | K77: CMP-1009 | L77: 825.64 | M77: 1108.43 | N77: 0.114 | O77: 7
A78: ORD-2024-446699 | B78: 45532 | C78: 45560 | D78: Americas | E78: Brazil | F78: Rio de Janeiro | G78: Non-Profit | H78: Online | J78: Accessories | K78: ACC-4490 | L78: 1394.65 | M78: 3144.1 | N78: 0.134 | O78: 13
A79: ORD-2024-451005 | B79: 45473 | C79: 45471 | D79: Americas | E79: Brazil | F79: Rio de Janeiro | G79: Small Business | H79: Direct | I79: L. Okafor | J79: Accessories | K79: ACC-9162 | L79: 1112.98 | M79: 2095.73 | N79: 0.072 | O79: 17
A80: ORD-2023-290279 | B80: 45091 | C80: 45093 | D80: Europe | E80: United Kingdom | F80: Manchester | G80: Non-Profit | H80: Direct | I80: K. Singh | J80: Components | K80: CMP-5820 | L80: 357.36 | M80: 703.62 | N80: 0.257 | O80: 20
A81: ORD-2024-192263 | B81: 45617 | C81: 45647 | D81: Europe | E81: France | F81: Marseille | G81: Small Business | H81: Direct | I81: I. Johnson | J81: Monitors | K81: MON-7943 | L81: 1122.68 | M81: 1997.19 | N81: 0.186 | O81: 3
A82: ORD-2023-159379 | B82: 44965 | C82: 44968 | D82: Africa | E82: South Africa | F82: Cape Town | G82: Corporate | H82: Direct | I82: M. Rossi | J82: Networking | K82: NET-5018 | L82: 1410.05 | M82: 2763.95 | N82: 0.161 | O82: 26
A83: ORD-2023-343322 | B83: 45157 | C83: 45181 | D83: Americas | E83: Canada | F83: Vancouver | G83: Enterprise | H83: Retail | I83: I. Johnson | J83: Printers | K83: PRN-9669 | L83: 1183.95 | M83: 1503.53 | N83: 0.241 | O83: 16
A84: ORD-2025-114382 | B84: 45791 | C84: 45801 | D84: Europe | E84: France | F84: Paris | G84: Small Business | H84: Marketplace | I84: K. Singh | J84: Components | K84: CMP-2865 | L84: 170.39 | M84: 388.04 | N84: 0.084 | O84: 15
A85: ORD-2025-488349 | B85: 45770 | C85: 45769 | D85: Americas | E85: USA | F85: San Francisco | G85: Non-Profit | H85: Distributor | I85: D. Smith | J85: Monitors | K85: MON-3371 | L85: 23.24 | M85: 44.57 | N85: 0.215 | O85: 15
A86: ORD-2025-330203 | B86: 45741 | C86: 45764 | D86: Europe | E86: United Kingdom | F86: London | G86: Consumer | H86: Retail | I86: H. Kim | J86: Networking | K86: NET-7166 | L86: 1421.19 | M86: 1808.26 | N86: 0.104 | O86: 13
A87: ORD-2023-841426 | B87: 45282 | C87: 45283 | D87: Africa | E87: South Africa | F87: Cape Town | G87: Non-Profit | H87: Marketplace | I87: D. Smith | J87: Components | K87: CMP-4531 | L87: 1186.18 | M87: 1285.09 | N87: 0.07 | O87: 11
A88: ORD-2024-594592 | B88: 45388 | C88: 45407 | D88: Asia | E88: China | F88: Shanghai | G88: Corporate | H88: Retail | I88: K. Singh | J88: Components | K88: CMP-8196 | L88: 1366.48 | M88: 1678.14 | N88: 0.154 | O88: 10
A89: ORD-2025-863978 | B89: 45876 | C89: 45888 | D89: Africa | E89: Kenya | F89: Nakuru | G89: Corporate | I89: M. Rossi | J89: Components | K89: CMP-2854 | L89: 601.51 | M89: 679.35 | N89: 0.188 | O89: 3
...

Sheet Excel_Assignment
A1: OrderID | B1: OrderDate | C1: RD(Original) | D1: DateDifference | E1: DateCategoty | F1: RequiredDate(est) | G1: LeadTimeDays | H1: Region | I1: Country | J1: City | K1: CustomerSegment | L1: Channel | M1: Salesperson | N1: ProductCategory | O1: SKU | P1: UnitCost | Q1: UP | R1: UnitPrice | S1: DiscountPct(%) | T1: Quantity | U1: GrossRevenue | V1: CostOfGoods | W1: GrossProfit | X1: MarginPct(%) | Y1: Month(OD) | Z1: OrderMonth | AA1: FirstOrderMonth | AB1: MonthsSinceFirstOrder | AC1: Quarter(OD) | AD1: RegionHierarchy | AE1: 33rd percentile(P33) | AF1: 66th percentile(P66) | AG1: PriceBand | AH1: Met7DayTarget | AI1: HighDiscountFlag | AJ1: Scenario_DiscountPct | AK1: Scenario_UnitCost | AL1: Scenario_Quantity | AM1: Scenario_GrossRevenue | AN1: Scenario_CostOfGoods | AO1: Scenario_GrossProfit | AP1: Scenario_MarginPct | AQ1: Delta_GrossRevenue | AR1: Delta_GrossProfit | AS1: OnTime %
A2: ORD-2024-275203 | B2: 45362 | C2: 45388 | D2: =C2-B2 -> 26 | E2: =IF(C2<B2,"Corrected","Original") -> Original | F2: =IF(D2=-1,B2+1,IF(D2=-2,B2+2,C2)) -> 45388 | G2: =F2-B2 -> 26 | H2: Africa | I2: Kenya | J2: Kisumu | K2: Corporate | L2: Retail | M2: C. Otieno | N2: Components | O2: CMP-8270 | P2: 279.24 | Q2: 608.9 | R2: =IF(Q2<0,-Q2,Q2) -> 608.9 | S2: 0.112 | T2: 9 | U2: =R2 * T2 * (1 - S2) -> 4866.3288 | V2: =P2*T2 -> 2513.16 | W2: =U2-V2 -> 2353.1688 | X2: =IF(U2=0, 0, W2/U2) -> 0.48356141 | Y2: =TEXT(B2,"MMM-YYYY") -> Mar-2024 | Z2: =DATE(YEAR(B2),MONTH(B2),1) -> 45352 | AA2: =_xlfn.MINIFS(Z:Z,I:I, I2) -> 44927 | AB2: =IF(Z2<AA2, " ", DATEDIF(AA2, Z2, "M")) -> 14 | AC2: ="Q"&ROUNDUP(MONTH(B2)/3,0)&"-"&YEAR(B2) -> Q1-2024 | AD2: =H2 & " → " & I2 & " → " & J2 -> Africa → Kenya → Kisumu | AE2: =_xlfn.PERCENTILE.INC($R:$R,0.33) -> 816.0801 | AF2: =_xlfn.PERCENTILE.INC($R:$R,0.66) -> 1619.115 | AG2: =IF(R2<=$AE$2,"Low",IF(R2<=$AF$2,"Medium","High")) -> Low | AH2: =IF(G2<=7,1,0) -> 0 | AI2: =IF(S2>0.2,1,0) -> 0 | AJ2: =MIN(S2, WhatIf_Panel!$B$2) -> 0.112 | AK2: =P2 * (1 + WhatIf_Panel!$B$3) -> 307.164 | AL2: =ROUND(T2 * (1 + WhatIf_Panel!$B$4), 0) -> 9 | AM2: =R2 * AL2 * (1 - AJ2) -> 4866.3288 | AN2: =AK2 * AL2 -> 2764.476 | AO2: =AM2 - AN2 -> 2101.8528 | AP2: =IF(AM2=0, 0, AO2/AM2) -> 0.43191755 | AQ2: =AM2 - U2 -> 0 | AR2: =AO2 - W2 -> -251.316 | AS2: =SUM(Excel_Assignment!AH:AH) / COUNTA(Excel_Assignment!A:A) -> 0.27172196
A3: ORD-2024-358795 | B3: 45588 | C3: 45587 | D3: =C3-B3 -> -1 | E3: =IF(C3<B3,"Corrected","Original") -> Corrected | F3: =IF(D3=-1,B3+1,IF(D3=-2,B3+2,C3)) -> 45589 | G3: =F3-B3 -> 1 | H3: Africa | I3: Nigeria | J3: Port Harcourt | K3: Education | L3: Online | M3: J. Njeri | N3: Printers | O3: PRN-9322 | P3: 1084.39 | Q3: 759.33 | R3: =IF(Q3<0,-Q3,Q3) -> 759.33 | S3: 0.237 | T3: 31 | U3: =R3 * T3 * (1 - S3) -> 17960.432 | V3: =P3*T3 -> 33616.09 | W3: =U3-V3 -> -15655.658 | X3: =IF(U3=0, 0, W3/U3) -> -0.87167486 | Y3: =TEXT(B3,"MMM-YYYY") -> Oct-2024 | Z3: =DATE(YEAR(B3),MONTH(B3),1) -> 45566 | AA3: =_xlfn.MINIFS(Z:Z,I:I, I3) -> 44927 | AB3: =IF(Z3<AA3, " ", DATEDIF(AA3, Z3, "M")) -> 21 | AC3: ="Q"&ROUNDUP(MONTH(B3)/3,0)&"-"&YEAR(B3) -> Q4-2024 | AD3: =H3 & " → " & I3 & " → " & J3 -> Africa → Nigeria → Port Harcourt | AG3: =IF(R3<=$AE$2,"Low",IF(R3<=$AF$2,"Medium","High")) -> Low | AH3: =IF(G3<=7,1,0) -> 1 | AI3: =IF(S3>0.2,1,0) -> 1 | AJ3: =MIN(S3, WhatIf_Panel!$B$2) -> 0.237 | AK3: =P3 * (1 + WhatIf_Panel!$B$3) -> 1192.829 | AL3: =ROUND(T3 * (1 + WhatIf_Panel!$B$4), 0) -> 33 | AM3: =R3 * AL3 * (1 - AJ3) -> 19119.17 | AN3: =AK3 * AL3 -> 39363.357 | AO3: =AM3 - AN3 -> -20244.187 | AP3: =IF(AM3=0, 0, AO3/AM3) -> -1.0588423 | AQ3: =AM3 - U3 -> 1158.7376 | AR3: =AO3 - W3 -> -4588.5294
A4: ORD-2023-373538 | B4: 44985 | C4: 45010 | D4: =C4-B4 -> 25 | E4: =IF(C4<B4,"Corrected","Original") -> Original | F4: =IF(D4=-1,B4+1,IF(D4=-2,B4+2,C4)) -> 45010 | G4: =F4-B4 -> 25 | H4: Africa | I4: Kenya | J4: Nairobi | K4: Corporate | L4: Retail | M4: I. Johnson | N4: Networking | O4: NET-9666 | P4: 1460.76 | Q4: -30.66 | R4: =IF(Q4<0,-Q4,Q4) -> 30.66 | S4: 0.131 | T4: 12 | U4: =R4 * T4 * (1 - S4) -> 319.72248 | V4: =P4*T4 -> 17529.12 | W4: =U4-V4 -> -17209.398 | X4: =IF(U4=0, 0, W4/U4) -> -53.826048 | Y4: =TEXT(B4,"MMM-YYYY") -> Feb-2023 | Z4: =DATE(YEAR(B4),MONTH(B4),1) -> 44958 | AA4: =_xlfn.MINIFS(Z:Z,I:I, I4) -> 44927 | AB4: =IF(Z4<AA4, " ", DATEDIF(AA4, Z4, "M")) -> 1 | AC4: ="Q"&ROUNDUP(MONTH(B4)/3,0)&"-"&YEAR(B4) -> Q1-2023 | AD4: =H4 & " → " & I4 & " → " & J4 -> Africa → Kenya → Nairobi | AG4: =IF(R4<=$AE$2,"Low",IF(R4<=$AF$2,"Medium","High")) -> Low | AH4: =IF(G4<=7,1,0) -> 0 | AI4: =IF(S4>0.2,1,0) -> 0 | AJ4: =MIN(S4, WhatIf_Panel!$B$2) -> 0.131 | AK4: =P4 * (1 + WhatIf_Panel!$B$3) -> 1606.836 | AL4: =ROUND(T4 * (1 + WhatIf_Panel!$B$4), 0) -> 13 | AM4: =R4 * AL4 * (1 - AJ4) -> 346.36602 | AN4: =AK4 * AL4 -> 20888.868 | AO4: =AM4 - AN4 -> -20542.502 | AP4: =IF(AM4=0, 0, AO4/AM4) -> -59.308653 | AQ4: =AM4 - U4 -> 26.64354 | AR4: =AO4 - W4 -> -3333.1045
A5: ORD-2025-168148 | B5: 45745 | C5: 45749 | D5: =C5-B5 -> 4 | E5: =IF(C5<B5,"Corrected","Original") -> Original | F5: =IF(D5=-1,B5+1,IF(D5=-2,B5+2,C5)) -> 45749 | G5: =F5-B5 -> 4 | H5: Africa | I5: Nigeria | J5: Lagos | K5: Non-Profit | L5: Marketplace | M5: G. Dubois | N5: Phones | O5: PHN-4556 | P5: 259.93 | Q5: 255.94 | R5: =IF(Q5<0,-Q5,Q5) -> 255.94 | S5: 0.072 | T5: 22 | U5: =R5 * T5 * (1 - S5) -> 5225.271 | V5: =P5*T5 -> 5718.46 | W5: =U5-V5 -> -493.18896 | X5: =IF(U5=0, 0, W5/U5) -> -0.094385335 | Y5: =TEXT(B5,"MMM-YYYY") -> Mar-2025 | Z5: =DATE(YEAR(B5),MONTH(B5),1) -> 45717 | AA5: =_xlfn.MINIFS(Z:Z,I:I, I5) -> 44927 | AB5: =IF(Z5<AA5, " ", DATEDIF(AA5, Z5, "M")) -> 26 | AC5: ="Q"&ROUNDUP(MONTH(B5)/3,0)&"-"&YEAR(B5) -> Q1-2025 | AD5: =H5 & " → " & I5 & " → " & J5 -> Africa → Nigeria → Lagos | AG5: =IF(R5<=$AE$2,"Low",IF(R5<=$AF$2,"Medium","High")) -> Low | AH5: =IF(G5<=7,1,0) -> 1 | AI5: =IF(S5>0.2,1,0) -> 0 | AJ5: =MIN(S5, WhatIf_Panel!$B$2) -> 0.072 | AK5: =P5 * (1 + WhatIf_Panel!$B$3) -> 285.923 | AL5: =ROUND(T5 * (1 + WhatIf_Panel!$B$4), 0) -> 23 | AM5: =R5 * AL5 * (1 - AJ5) -> 5462.7834 | AN5: =AK5 * AL5 -> 6576.229 | AO5: =AM5 - AN5 -> -1113.4456 | AP5: =IF(AM5=0, 0, AO5/AM5) -> -0.20382387 | AQ5: =AM5 - U5 -> 237.51232 | AR5: =AO5 - W5 -> -620.25668
A6: ORD-2023-824839 | B6: 45266 | C6: 45291 | D6: =C6-B6 -> 25 | E6: =IF(C6<B6,"Corrected","Original") -> Original | F6: =IF(D6=-1,B6+1,IF(D6=-2,B6+2,C6)) -> 45291 | G6: =F6-B6 -> 25 | H6: Asia | I6: Japan | J6: Osaka | K6: Consumer | L6: Retail | M6: L. Okafor | N6: Printers | O6: PRN-8041 | P6: 663.03 | Q6: 813.51 | R6: =IF(Q6<0,-Q6,Q6) -> 813.51 | S6: 0.102 | T6: 15 | U6: =R6 * T6 * (1 - S6) -> 10957.98 | V6: =P6*T6 -> 9945.45 | W6: =U6-V6 -> 1012.5297 | X6: =IF(U6=0, 0, W6/U6) -> 0.092401129 | Y6: =TEXT(B6,"MMM-YYYY") -> Dec-2023 | Z6: =DATE(YEAR(B6),MONTH(B6),1) -> 45261 | AA6: =_xlfn.MINIFS(Z:Z,I:I, I6) -> 44986 | AB6: =IF(Z6<AA6, " ", DATEDIF(AA6, Z6, "M")) -> 9 | AC6: ="Q"&ROUNDUP(MONTH(B6)/3,0)&"-"&YEAR(B6) -> Q4-2023 | AD6: =H6 & " → " & I6 & " → " & J6 -> Asia → Japan → Osaka | AG6: =IF(R6<=$AE$2,"Low",IF(R6<=$AF$2,"Medium","High")) -> Low | AH6: =IF(G6<=7,1,0) -> 0 | AI6: =IF(S6>0.2,1,0) -> 0 | AJ6: =MIN(S6, WhatIf_Panel!$B$2) -> 0.102 | AK6: =P6 * (1 + WhatIf_Panel!$B$3) -> 729.333 | AL6: =ROUND(T6 * (1 + WhatIf_Panel!$B$4), 0) -> 16 | AM6: =R6 * AL6 * (1 - AJ6) -> 11688.512 | AN6: =AK6 * AL6 -> 11669.328 | AO6: =AM6 - AN6 -> 19.18368 | AP6: =IF(AM6=0, 0, AO6/AM6) -> 0.0016412423 | AQ6: =AM6 - U6 -> 730.53198 | AR6: =AO6 - W6 -> -993.34602
A7: ORD-2023-723587 | B7: 44928 | C7: 44931 | D7: =C7-B7 -> 3 | E7: =IF(C7<B7,"Corrected","Original") -> Original | F7: =IF(D7=-1,B7+1,IF(D7=-2,B7+2,C7)) -> 44931 | G7: =F7-B7 -> 3 | H7: Americas | I7: Canada | J7: Toronto | K7: Corporate | L7: Distributor | M7: B. Chen | N7: Laptops | O7: LAP-8555 | P7: 315.87 | Q7: 591.68 | R7: =IF(Q7<0,-Q7,Q7) -> 591.68 | S7: 0 | T7: 7 | U7: =R7 * T7 * (1 - S7) -> 4141.76 | V7: =P7*T7 -> 2211.09 | W7: =U7-V7 -> 1930.67 | X7: =IF(U7=0, 0, W7/U7) -> 0.46614724 | Y7: =TEXT(B7,"MMM-YYYY") -> Jan-2023 | Z7: =DATE(YEAR(B7),MONTH(B7),1) -> 44927 | AA7: =_xlfn.MINIFS(Z:Z,I:I, I7) -> 44927 | AB7: =IF(Z7<AA7, " ", DATEDIF(AA7, Z7, "M")) -> 0 | AC7: ="Q"&ROUNDUP(MONTH(B7)/3,0)&"-"&YEAR(B7) -> Q1-2023 | AD7: =H7 & " → " & I7 & " → " & J7 -> Americas → Canada → Toronto | AG7: =IF(R7<=$AE$2,"Low",IF(R7<=$AF$2,"Medium","High")) -> Low | AH7: =IF(G7<=7,1,0) -> 1 | AI7: =IF(S7>0.2,1,0) -> 0 | AJ7: =MIN(S7, WhatIf_Panel!$B$2) -> 0 | AK7: =P7 * (1 + WhatIf_Panel!$B$3) -> 347.457 | AL7: =ROUND(T7 * (1 + WhatIf_Panel!$B$4), 0) -> 7 | AM7: =R7 * AL7 * (1 - AJ7) -> 4141.76 | AN7: =AK7 * AL7 -> 2432.199 | AO7: =AM7 - AN7 -> 1709.561 | AP7: =IF(AM7=0, 0, AO7/AM7) -> 0.41276197 | AQ7: =AM7 - U7 -> 0 | AR7: =AO7 - W7 -> -221.109
A8: ORD-2024-336584 | B8: 45653 | C8: 45671 | D8: =C8-B8 -> 18 | E8: =IF(C8<B8,"Corrected","Original") -> Original | F8: =IF(D8=-1,B8+1,IF(D8=-2,B8+2,C8)) -> 45671 | G8: =F8-B8 -> 18 | H8: Asia | I8: India | J8: Bengaluru | K8: Small Business | L8: Marketplace | M8: E. Garcia | N8: Monitors | O8: MON-8629 | P8: 586.07 | Q8: 845.97 | R8: =IF(Q8<0,-Q8,Q8) -> 845.97 | S8: 0.147 | T8: 4 | U8: =R8 * T8 * (1 - S8) -> 2886.4496 | V8: =P8*T8 -> 2344.28 | W8: =U8-V8 -> 542.16964 | X8: =IF(U8=0, 0, W8/U8) -> 0.1878327 | Y8: =TEXT(B8,"MMM-YYYY") -> Dec-2024 | Z8: =DATE(YEAR(B8),MONTH(B8),1) -> 45627 | AA8: =_xlfn.MINIFS(Z:Z,I:I, I8) -> 44927 | AB8: =IF(Z8<AA8, " ", DATEDIF(AA8, Z8, "M")) -> 23 | AC8: ="Q"&ROUNDUP(MONTH(B8)/3,0)&"-"&YEAR(B8) -> Q4-2024 | AD8: =H8 & " → " & I8 & " → " & J8 -> Asia → India → Bengaluru | AG8: =IF(R8<=$AE$2,"Low",IF(R8<=$AF$2,"Medium","High")) -> Medium | AH8: =IF(G8<=7,1,0) -> 0 | AI8: =IF(S8>0.2,1,0) -> 0 | AJ8: =MIN(S8, WhatIf_Panel!$B$2) -> 0.147 | AK8: =P8 * (1 + WhatIf_Panel!$B$3) -> 644.677 | AL8: =ROUND(T8 * (1 + WhatIf_Panel!$B$4), 0) -> 4 | AM8: =R8 * AL8 * (1 - AJ8) -> 2886.4496 | AN8: =AK8 * AL8 -> 2578.708 | AO8: =AM8 - AN8 -> 307.74164 | AP8: =IF(AM8=0, 0, AO8/AM8) -> 0.10661597 | AQ8: =AM8 - U8 -> 0 | AR8: =AO8 - W8 -> -234.428
A9: ORD-2023-112666 | B9: 44941 | C9: 44939 | D9: =C9-B9 -> -2 | E9: =IF(C9<B9,"Corrected","Original") -> Corrected | F9: =IF(D9=-1,B9+1,IF(D9=-2,B9+2,C9)) -> 44943 | G9: =F9-B9 -> 2 | H9: Africa | I9: Nigeria | J9: Abuja | K9: Education | L9: Online | M9: O. Wang | N9: Printers | O9: PRN-6276 | P9: 28.38 | Q9: 47.22 | R9: =IF(Q9<0,-Q9,Q9) -> 47.22 | S9: 0.194 | T9: 18 | U9: =R9 * T9 * (1 - S9) -> 685.06776 | V9: =P9*T9 -> 510.84 | W9: =U9-V9 -> 174.22776 | X9: =IF(U9=0, 0, W9/U9) -> 0.25432194 | Y9: =TEXT(B9,"MMM-YYYY") -> Jan-2023 | Z9: =DATE(YEAR(B9),MONTH(B9),1) -> 44927 | AA9: =_xlfn.MINIFS(Z:Z,I:I, I9) -> 44927 | AB9: =IF(Z9<AA9, " ", DATEDIF(AA9, Z9, "M")) -> 0 | AC9: ="Q"&ROUNDUP(MONTH(B9)/3,0)&"-"&YEAR(B9) -> Q1-2023 | AD9: =H9 & " → " & I9 & " → " & J9 -> Africa → Nigeria → Abuja | AG9: =IF(R9<=$AE$2,"Low",IF(R9<=$AF$2,"Medium","High")) -> Low | AH9: =IF(G9<=7,1,0) -> 1 | AI9: =IF(S9>0.2,1,0) -> 0 | AJ9: =MIN(S9, WhatIf_Panel!$B$2) -> 0.194 | AK9: =P9 * (1 + WhatIf_Panel!$B$3) -> 31.218 | AL9: =ROUND(T9 * (1 + WhatIf_Panel!$B$4), 0) -> 19 | AM9: =R9 * AL9 * (1 - AJ9) -> 723.12708 | AN9: =AK9 * AL9 -> 593.142 | AO9: =AM9 - AN9 -> 129.98508 | AP9: =IF(AM9=0, 0, AO9/AM9) -> 0.17975413 | AQ9: =AM9 - U9 -> 38.05932 | AR9: =AO9 - W9 -> -44.24268
A10: ORD-2024-589570 | B10: 45416 | C10: 45441 | D10: =C10-B10 -> 25 | E10: =IF(C10<B10,"Corrected","Original") -> Original | F10: =IF(D10=-1,B10+1,IF(D10=-2,B10+2,C10)) -> 45441 | G10: =F10-B10 -> 25 | H10: Africa | I10: Nigeria | J10: Abuja | K10: Non-Profit | L10: Marketplace | M10: O. Wang | N10: Monitors | O10: MON-6892 | P10: 1295.34 | Q10: 2530.81 | R10: =IF(Q10<0,-Q10,Q10) -> 2530.81 | S10: 0.031 | T10: 6 | U10: =R10 * T10 * (1 - S10) -> 14714.129 | V10: =P10*T10 -> 7772.04 | W10: =U10-V10 -> 6942.0893 | X10: =IF(U10=0, 0, W10/U10) -> 0.47179749 | Y10: =TEXT(B10,"MMM-YYYY") -> May-2024 | Z10: =DATE(YEAR(B10),MONTH(B10),1) -> 45413 | AA10: =_xlfn.MINIFS(Z:Z,I:I, I10) -> 44927 | AB10: =IF(Z10<AA10, " ", DATEDIF(AA10, Z10, "M")) -> 16 | AC10: ="Q"&ROUNDUP(MONTH(B10)/3,0)&"-"&YEAR(B10) -> Q2-2024 | AD10: =H10 & " → " & I10 & " → " & J10 -> Africa → Nigeria → Abuja | AG10: =IF(R10<=$AE$2,"Low",IF(R10<=$AF$2,"Medium","High")) -> High | AH10: =IF(G10<=7,1,0) -> 0 | AI10: =IF(S10>0.2,1,0) -> 0 | AJ10: =MIN(S10, WhatIf_Panel!$B$2) -> 0.031 | AK10: =P10 * (1 + WhatIf_Panel!$B$3) -> 1424.874 | AL10: =ROUND(T10 * (1 + WhatIf_Panel!$B$4), 0) -> 6 | AM10: =R10 * AL10 * (1 - AJ10) -> 14714.129 | AN10: =AK10 * AL10 -> 8549.244 | AO10: =AM10 - AN10 -> 6164.8853 | AP10: =IF(AM10=0, 0, AO10/AM10) -> 0.41897724 | AQ10: =AM10 - U10 -> 0 | AR10: =AO10 - W10 -> -777.204
A11: ORD-2025-997421 | B11: 45798 | C11: 45817 | D11: =C11-B11 -> 19 | E11: =IF(C11<B11,"Corrected","Original") -> Original | F11: =IF(D11=-1,B11+1,IF(D11=-2,B11+2,C11)) -> 45817 | G11: =F11-B11 -> 19 | H11: Americas | I11: Brazil | J11: São Paulo | K11: Non-Profit | L11: Online | M11: A. Patel | N11: Components | O11: CMP-3731 | P11: 1331.38 | Q11: 2309.56 | R11: =IF(Q11<0,-Q11,Q11) -> 2309.56 | S11: 0.149 | T11: 31 | U11: =R11 * T11 * (1 - S11) -> 60928.502 | V11: =P11*T11 -> 41272.78 | W11: =U11-V11 -> 19655.722 | X11: =IF(U11=0, 0, W11/U11) -> 0.32260308 | Y11: =TEXT(B11,"MMM-YYYY") -> May-2025 | Z11: =DATE(YEAR(B11),MONTH(B11),1) -> 45778 | AA11: =_xlfn.MINIFS(Z:Z,I:I, I11) -> 44927 | AB11: =IF(Z11<AA11, " ", DATEDIF(AA11, Z11, "M")) -> 28 | AC11: ="Q"&ROUNDUP(MONTH(B11)/3,0)&"-"&YEAR(B11) -> Q2-2025 | AD11: =H11 & " → " & I11 & " → " & J11 -> Americas → Brazil → São Paulo | AG11: =IF(R11<=$AE$2,"Low",IF(R11<=$AF$2,"Medium","High")) -> High | AH11: =IF(G11<=7,1,0) -> 0 | AI11: =IF(S11>0.2,1,0) -> 0 | AJ11: =MIN(S11, WhatIf_Panel!$B$2) -> 0.149 | AK11: =P11 * (1 + WhatIf_Panel!$B$3) -> 1464.518 | AL11: =ROUND(T11 * (1 + WhatIf_Panel!$B$4), 0) -> 33 | AM11: =R11 * AL11 * (1 - AJ11) -> 64859.373 | AN11: =AK11 * AL11 -> 48329.094 | AO11: =AM11 - AN11 -> 16530.279 | AP11: =IF(AM11=0, 0, AO11/AM11) -> 0.25486339 | AQ11: =AM11 - U11 -> 3930.8711 | AR11: =AO11 - W11 -> -3125.4429
A12: ORD-2024-210687 | B12: 45319 | C12: 45331 | D12: =C12-B12 -> 12 | E12: =IF(C12<B12,"Corrected","Original") -> Original | F12: =IF(D12=-1,B12+1,IF(D12=-2,B12+2,C12)) -> 45331 | G12: =F12-B12 -> 12 | H12: Europe | I12: Germany | J12: Berlin | K12: Corporate | L12: Online | M12: G. Dubois | N12: Accessories | O12: ACC-7938 | P12: 644.17 | Q12: 700.12 | R12: =IF(Q12<0,-Q12,Q12) -> 700.12 | S12: 0.006 | T12: 23 | U12: =R12 * T12 * (1 - S12) -> 16006.143 | V12: =P12*T12 -> 14815.91 | W12: =U12-V12 -> 1190.2334 | X12: =IF(U12=0, 0, W12/U12) -> 0.074361038 | Y12: =TEXT(B12,"MMM-YYYY") -> Jan-2024 | Z12: =DATE(YEAR(B12),MONTH(B12),1) -> 45292 | AA12: =_xlfn.MINIFS(Z:Z,I:I, I12) -> 44927 | AB12: =IF(Z12<AA12, " ", DATEDIF(AA12, Z12, "M")) -> 12 | AC12: ="Q"&ROUNDUP(MONTH(B12)/3,0)&"-"&YEAR(B12) -> Q1-2024 | AD12: =H12 & " → " & I12 & " → " & J12 -> Europe → Germany → Berlin | AG12: =IF(R12<=$AE$2,"Low",IF(R12<=$AF$2,"Medium","High")) -> Low | AH12: =IF(G12<=7,1,0) -> 0 | AI12: =IF(S12>0.2,1,0) -> 0 | AJ12: =MIN(S12, WhatIf_Panel!$B$2) -> 0.006 | AK12: =P12 * (1 + WhatIf_Panel!$B$3) -> 708.587 | AL12: =ROUND(T12 * (1 + WhatIf_Panel!$B$4), 0) -> 24 | AM12: =R12 * AL12 * (1 - AJ12) -> 16702.063 | AN12: =AK12 * AL12 -> 17006.088 | AO12: =AM12 - AN12 -> -304.02528 | AP12: =IF(AM12=0, 0, AO12/AM12) -> -0.018202858 | AQ12: =AM12 - U12 -> 695.91928 | AR12: =AO12 - W12 -> -1494.2587
A13: ORD-2025-515515 | B13: 45660 | C13: 45680 | D13: =C13-B13 -> 20 | E13: =IF(C13<B13,"Corrected","Original") -> Original | F13: =IF(D13=-1,B13+1,IF(D13=-2,B13+2,C13)) -> 45680 | G13: =F13-B13 -> 20 | H13: Asia | I13: Japan | J13: Osaka | K13: Corporate | L13: Distributor | M13: F. Müller | N13: Phones | O13: PHN-7019 | P13: 908.6 | Q13: 691.37 | R13: =IF(Q13<0,-Q13,Q13) -> 691.37 | S13: 0.25 | T13: 20 | U13: =R13 * T13 * (1 - S13) -> 10370.55 | V13: =P13*T13 -> 18172 | W13: =U13-V13 -> -7801.45 | X13: =IF(U13=0, 0, W13/U13) -> -0.75226965 | Y13: =TEXT(B13,"MMM-YYYY") -> Jan-2025 | Z13: =DATE(YEAR(B13),MONTH(B13),1) -> 45658 | AA13: =_xlfn.MINIFS(Z:Z,I:I, I13) -> 44986 | AB13: =IF(Z13<AA13, " ", DATEDIF(AA13, Z13, "M")) -> 22 | AC13: ="Q"&ROUNDUP(MONTH(B13)/3,0)&"-"&YEAR(B13) -> Q1-2025 | AD13: =H13 & " → " & I13 & " → " & J13 -> Asia → Japan → Osaka | AG13: =IF(R13<=$AE$2,"Low",IF(R13<=$AF$2,"Medium","High")) -> Low | AH13: =IF(G13<=7,1,0) -> 0 | AI13: =IF(S13>0.2,1,0) -> 1 | AJ13: =MIN(S13, WhatIf_Panel!$B$2) -> 0.25 | AK13: =P13 * (1 + WhatIf_Panel!$B$3) -> 999.46 | AL13: =ROUND(T13 * (1 + WhatIf_Panel!$B$4), 0) -> 21 | AM13: =R13 * AL13 * (1 - AJ13) -> 10889.077 | AN13: =AK13 * AL13 -> 20988.66 | AO13: =AM13 - AN13 -> -10099.583 | AP13: =IF(AM13=0, 0, AO13/AM13) -> -0.92749661 | AQ13: =AM13 - U13 -> 518.5275 | AR13: =AO13 - W13 -> -2298.1325
A14: ORD-2025-487261 | B14: 45722 | C14: 45747 | D14: =C14-B14 -> 25 | E14: =IF(C14<B14,"Corrected","Original") -> Original | F14: =IF(D14=-1,B14+1,IF(D14=-2,B14+2,C14)) -> 45747 | G14: =F14-B14 -> 25 | H14: Americas | I14: Brazil | J14: Brasília | K14: Non-Profit | L14: Online | M14: J. Njeri | N14: Components | O14: CMP-3693 | P14: 331.57 | Q14: 548.4 | R14: =IF(Q14<0,-Q14,Q14) -> 548.4 | S14: 0.094 | T14: 10 | U14: =R14 * T14 * (1 - S14) -> 4968.504 | V14: =P14*T14 -> 3315.7 | W14: =U14-V14 -> 1652.804 | X14: =IF(U14=0, 0, W14/U14) -> 0.33265627 | Y14: =TEXT(B14,"MMM-YYYY") -> Mar-2025 | Z14: =DATE(YEAR(B14),MONTH(B14),1) -> 45717 | AA14: =_xlfn.MINIFS(Z:Z,I:I, I14) -> 44927 | AB14: =IF(Z14<AA14, " ", DATEDIF(AA14, Z14, "M")) -> 26 | AC14: ="Q"&ROUNDUP(MONTH(B14)/3,0)&"-"&YEAR(B14) -> Q1-2025 | AD14: =H14 & " → " & I14 & " → " & J14 -> Americas → Brazil → Brasília | AG14: =IF(R14<=$AE$2,"Low",IF(R14<=$AF$2,"Medium","High")) -> Low | AH14: =IF(G14<=7,1,0) -> 0 | AI14: =IF(S14>0.2,1,0) -> 0 | AJ14: =MIN(S14, WhatIf_Panel!$B$2) -> 0.094 | AK14: =P14 * (1 + WhatIf_Panel!$B$3) -> 364.727 | AL14: =ROUND(T14 * (1 + WhatIf_Panel!$B$4), 0) -> 11 | AM14: =R14 * AL14 * (1 - AJ14) -> 5465.3544 | AN14: =AK14 * AL14 -> 4011.997 | AO14: =AM14 - AN14 -> 1453.3574 | AP14: =IF(AM14=0, 0, AO14/AM14) -> 0.2659219 | AQ14: =AM14 - U14 -> 496.8504 | AR14: =AO14 - W14 -> -199.4466
... A633: ORD-2025-728935 | B633: 45716 | C633: 45726 | D633: =C633-B633 -> 10 | E633: =IF(C633<B633,"Corrected","Original") -> Original | F633: =IF(D633=-1,B633+1,IF(D633=-2,B633+2,C633)) -> 45726 | G633: =F633-B633 -> 10 | H633: Asia | I633: Japan | J633: Osaka | K633: Education | L633: Distributor | M633: N. Brown | N633: Laptops | O633: LAP-3017 | P633: 51.86 | Q633: 45.98 | R633: =IF(Q633<0,-Q633,Q633) -> 45.98 | S633: 0.173 | T633: 7 | U633: =R633 * T633 * (1 - S633) -> 266.17822 | V633: =P633*T633 -> 363.02 | W633: =U633-V633 -> -96.84178 | X633: =IF(U633=0, 0, W633/U633) -> -0.36382308 | Y633: =TEXT(B633,"MMM-YYYY") -> Feb-2025 | Z633: =DATE(YEAR(B633),MONTH(B633),1) -> 45689 | AA633: =_xlfn.MINIFS(Z:Z,I:I, I633) -> 44986 | AB633: =IF(Z633<AA633, " ", DATEDIF(AA633, Z633, "M")) -> 23 | AC633: ="Q"&ROUNDUP(MONTH(B633)/3,0)&"-"&YEAR(B633) -> Q1-2025 | AD633: =H633 & " → " & I633 & " → " & J633 -> Asia → Japan → Osaka | AG633: =IF(R633<=$AE$2,"Low",IF(R633<=$AF$2,"Medium","High")) -> Low | AH633: =IF(G633<=7,1,0) -> 0 | AI633: =IF(S633>0.2,1,0) -> 0 | AJ633: =MIN(S633, WhatIf_Panel!$B$2) -> 0.173 | AK633: =P633 * (1 + WhatIf_Panel!$B$3) -> 57.046 | AL633: =ROUND(T633 * (1 + WhatIf_Panel!$B$4), 0) -> 7 | AM633: =R633 * AL633 * (1 - AJ633) -> 266.17822 | AN633: =AK633 * AL633 -> 399.322 | AO633: =AM633 - AN633 -> -133.14378 | AP633: =IF(AM633=0, 0, AO633/AM633) -> -0.50020539 | AQ633: =AM633 - U633 -> 0 | AR633: =AO633 - W633 -> -36.302

Sheet Brief
A1: Assignment
A2: Excel Mastery Assignment: Sales Operations & Analytics
A4: Overview:
A5: You are an analyst for a multi-regional electronics distributor. The 'Data' sheet contains 632 rows and 15 columns of transactional data with intentional data-quality issues.
A6: Your job is to clean, enrich, analyze, and present insights via a dynamic dashboard.
A8: Part A — Data Cleaning & Preparation:
A9: 1) Create a staging table where you:
A10: • Remove exact duplicate rows (define and document your duplicate criteria).
A11: • Fix data types (dates as Dates, numeric fields as numbers).
A12: • Handle missing values for City, Salesperson, and Channel using reasonable business logic (document your approach).
A13: • Flag and correct suspicious UnitPrice values (e.g., negative prices) and discounts (e.g., > 30%).
A14: • Ensure RequiredDate is not earlier than OrderDate; where it is, impute a corrected RequiredDate (explain your rule).
... A67: 15) Ensure your dashboard responds to slicers without broken references.

Sheet Cohort Analysis
A3: Sum of GrossRevenue | B3: CohortMonthsSinceFirstOrder Analysis
A4: Country | B4: 0 | C4: 1 | D4: 2 | E4: 3 | F4: 4 | G4: 5 | H4: 6 | I4: 7 | J4: 8 | K4: 9 | L4: 10 | M4: 11 | N4: 12 | O4: 13 | P4: 14 | Q4: 15 | R4: 16 | S4: 17 | T4: 18 | U4: 19 | V4: 20 | W4: 21 | X4: 22 | Y4: 23 | Z4: 24 | AA4: 25 | AB4: 26 | AC4: 27 | AD4: 28 | AE4: 29 | AF4: 30 | AG4: 31 | AH4: 32 | AI4: Grand Total
A5: Brazil | B5: 1801.4076 | C5: 24894.431 | D5: 24523.007 | E5: 12248.676 | F5: 27194.152 | G5: 46991.747 | H5: 93430.735 | I5: 37330.003 | J5: 7071.6331 | K5: 16213.633 | L5: 24161.263 | M5: 61471.697 | N5: 8567.3925 | O5: 39239.198 | P5: 110.1492 | Q5: 57491.063 | R5: 9469.7678 | S5: 41658.527 | T5: 10937.52 | U5: 41358.42 | V5: 85419.018 | X5: 11939.431 | Z5: 22987.328 | AA5: 70563.592 | AB5: 16257.34 | AC5: 68920.107 | AD5: 67158.245 | AF5: 38096.184 | AG5: 45754.744 | AH5: 24172.045 | AI5: 1037432.5
A6: Canada | B6: 4141.76 | C6: 26150.364 | D6: 17453.344 | E6: 15618.845 | G6: 46226.12 | H6: 29536.716 | I6: 52625.804 | J6: 15530.93 | K6: 27756.432 | M6: 14466.951 | N6: 19139.594 | O6: 9774.3888 | P6: 21931.504 | R6: 17930.495 | S6: 55516.604 | T6: 79082.507 | U6: 7466.3064 | V6: 64160.245 | X6: 60697.471 | Y6: 20713.04 | AA6: 8128.5187 | AC6: 7901.5042 | AD6: 76122.593 | AE6: 5335.5655 | AF6: 141645.57 | AG6: 24972.288 | AH6: 12597.522 | AI6: 882622.98
A7: China | B7: 11406.96 | C7: 10869.183 | D7: 13437.3 | E7: 23379.011 | F7: 49097.717 | G7: 5769.2758 | I7: 64096.735 | J7: 14108.168 | K7: 62366.338 | M7: 23668.56 | O7: 79081.561 | P7: 45749.976 | Q7: 14197.064 | S7: 70180.56 | T7: 50774.407 | V7: 21270.483 | W7: 68861.98 | X7: 4071.8 | Y7: 77129.274 | Z7: 56274.474 | AB7: 9378.6258 | AD7: 9684.8756 | AE7: 55548.647 | AF7: 20703.052 | AG7: 33684.351 | AI7: 894790.38
A8: France | B8: 9847.2359 | C8: 39546.775 | E8: 40811.052 | G8: 10388.43 | H8: 60768.603 | I8: 36549.429 | J8: 14877.464 | K8: 5159.7894 | L8: 22983.346 | M8: 28412.1 | N8: 29263.361 | O8: 20654.545 | P8: 45104.931 | Q8: 16219.345 | R8: 43635.435 | T8: 27907.425 | U8: 9189.1635 | W8: 41419.524 | X8: 67281.057 | Y8: 32011.667 | Z8: 20050.102 | AA8: 12040.644 | AC8: 33208.325 | AD8: 5331.6696 | AE8: 17419.587 | AG8: 68199.913 | AI8: 758280.92
A9: Germany | B9: 13921.506 | C9: 142962.67 | D9: 6271.3802 | E9: 104633.05 | F9: 17964.404 | G9: 5189.8836 | H9: 14114.069 | I9: 215.1984 | L9: 7643.265 | M9: 56963.241 | N9: 41020.91 | O9: 321.93291 | P9: 68292.728 | Q9: 37482.346 | R9: 32187.988 | S9: 65111.386 | U9: 47066.844 | X9: 12955.825 | Y9: 78869.294 | AA9: 30546.068 | AB9: 16870.42 | AC9: 5810.4845 | AD9: 10666.229 | AE9: 56166.984 | AG9: 56176.778 | AI9: 929424.89
A10: India | B10: 26759.288 | C10: 22044.871 | D10: 6631.6443 | E10: 32506.559 | F10: 249678.14 | G10: 4577.148 | H10: 12462.651 | I10: 7105.3528 | J10: 42824.197 | K10: 34805.041 | L10: 39388.574 | M10: 35984.637 | N10: 33792.866 | O10: 24305.883 | P10: 12668.507 | R10: 35554.1 | S10: 31513.423 | T10: 30229.995 | U10: 43785.688 | V10: 20028.787 | W10: 599.532 | X10: 91856.869 | Y10: 40695.915 | Z10: 33308.55 | AA10: 7120.6486 | AB10: 24075.09 | AC10: 4856.3573 | AD10: 62421.225 | AE10: 39717.144 | AG10: 11006.648 | AH10: 29627.32 | AI10: 1091932.6
A11: Japan | B11: 31024.839 | C11: 21196.913 | D11: 9062.3469 | E11: 4603.0824 | F11: 32142.114 | H11: 31130.742 | I11: 14527.748 | J11: 14268.608 | K11: 38506.529 | L11: 67110.666 | M11: 15253.07 | P11: 14287.896 | Q11: 68665.574 | R11: 23449.834 | S11: 82602.55 | T11: 50582.706 | U11: 29808.425 | W11: 18641.222 | X11: 15705.464 | Y11: 7955.6342 | Z11: 49494.319 | AA11: 20606.464 | AB11: 63856.507 | AC11: 11984.891 | AD11: 9315.4974 | AE11: 34082.865 | AF11: 74882.386 | AI11: 854748.89
A12: Kenya | B12: 47962.718 | C12: 3115.3609 | D12: 70602.928 | E12: 11003.767 | F12: 10946.712 | G12: 3799.8031 | H12: 36649.808 | I12: 667.74 | J12: 1030.7574 | K12: 38264.51 | M12: 16061.973 | O12: 66852.129 | P12: 4866.3288 | Q12: 24447.959 | R12: 13108.786 | S12: 181608.7 | T12: 27763.018 | U12: 3823.6152 | V12: 52863.981 | W12: 50650.006 | X12: 123535.74 | Z12: 52609.066 | AA12: 15860.782 | AB12: 13669.81 | AC12: 17731.623 | AD12: 4569.8508 | AF12: 17867.219 | AG12: 15174.426 | AH12: 9050.5053 | AI12: 936159.62
A13: Nigeria | B13: 685.06776 | C13: 4737.2198 | E13: 32280.325 | F13: 43539.233 | G13: 7135.57 | H13: 112088.82 | I13: 24833.098 | K13: 10786.321 | M13: 27158.894 | P13: 28041.025 | Q13: 48850.807 | R13: 68626.652 | S13: 15009.057 | V13: 2879.9836 | W13: 100069.72 | Y13: 12967.959 | AA13: 23687.576 | AB13: 52727.976 | AC13: 40139.875 | AD13: 1010.3759 | AE13: 55110.62 | AF13: 119970.85 | AG13: 49501.66 | AI13: 881838.68
A14: South Africa | B14: 3116.21 | C14: 86597.081 | D14: 29618.551 | F14: 15187.141 | H14: 78566.393 | I14: 58520.37 | K14: 434.45248 | L14: 12954.358 | M14: 79406.785 | N14: 54214.972 | P14: 4826.5396 | Q14: 20171.633 | R14: 14032.851 | S14: 39907.476 | U14: 27331.83 | V14: 12972.002 | W14: 18061.204 | Z14: 6576.299 | AB14: 5565.3273 | AC14: 1886.9916 | AD14: 31556.188 | AE14: 88311.187 | AF14: 76636.156 | AH14: 13185.543 | AI14: 779637.54
A15: United Kingdom | B15: 27965.367 | C15: 4132.0325 | D15: 16013.682 | E15: 66551.125 | F15: 19800.889 | G15: 29905.538 | H15: 48616.566 | I15: 31801.901 | K15: 26003.218 | L15: 5610.0924 | N15: 27424.45 | P15: 33938.143 | Q15: 20646.611 | R15: 114279.15 | S15: 65319.42 | U15: 23687.524 | V15: 25249.613 | W15: 91431.438 | X15: 44605.989 | Y15: 61319.075 | Z15: 11332.143 | AA15: 35720.318 | AB15: 21062.612 | AC15: 96832.738 | AD15: 39263.703 | AE15: 52414.751 | AF15: 62736.309 | AG15: 853.32277 | AH15: 8764.4066 | AI15: 1113282.1
A16: USA | B16: 31035.218 | C16: 68738.647 | E16: 11375.258 | F16: 27431.638 | G16: 71887.464 | H16: 32086.376 | I16: 25299.04 | J16: 14692.623 | K16: 5533.623 | N16: 18566.16 | O16: 52311.008 | P16: 108770.28 | R16: 53872.641 | T16: 25483.915 | U16: 97443.478 | V16: 12186.369 | W16: 16023.123 | Y16: 12031.492 | Z16: 4654.7743 | AA16: 9984.7161 | AC16: 38240.697 | AD16: 3644.3213 | AG16: 27401.728 | AI16: 768694.59
A17: Grand Total | B17: 209667.58 | C17: 454985.55 | D17: 193614.18 | E17: 355010.75 | F17: 492982.14 | G17: 231870.98 | H17: 549451.47 | I17: 353572.42 | J17: 124404.38 | K17: 265829.89 | L17: 179851.56 | M17: 358847.91 | N17: 231989.71 | O17: 292540.64 | P17: 388588.01 | Q17: 308172.4 | R17: 426147.7 | S17: 648427.7 | T17: 302761.49 | U17: 330961.29 | V17: 297030.48 | W17: 405757.75 | X17: 432649.65 | Y17: 343693.35 | Z17: 257287.06 | AA17: 234259.33 | AB17: 223463.71 | AC17: 327513.59 | AD17: 320744.77 | AE17: 404107.35 | AF17: 552537.72 | AG17: 332725.86 | AH17: 97397.342 | AI17: 10928846

Sheet SKURevPivot
A3: Row Labels | B3: Sum of GrossRevenue | C3: Sum of GrossRevenue2
A4: Networking | B4: 1774358.6 | C4: 0.16235554
A5: NET-2365 | B5: 109244 | C5: 0.061568163
A6: NET-5987 | B6: 82141.34 | C6: 0.046293539
A7: NET-5523 | B7: 79548.756 | C7: 0.0448324
A8: NET-1612 | B8: 66988.771 | C8: 0.037753795
A9: NET-5018 | B9: 60292.805 | C9: 0.033980056
A10: NET-1282 | B10: 51768.182 | C10: 0.029175715
A11: NET-4735 | B11: 50090.397 | C11: 0.028230143
A12: NET-3850 | B12: 49336.511 | C12: 0.027805265
A13: NET-6036 | B13: 47962.718 | C13: 0.027031017
A14: NET-3828 | B14: 47693.373 | C14: 0.026879219
A15: NET-3535 | B15: 43553.493 | C15: 0.024546049
... A641: Grand Total | B641: 10928846 | C641: 1

Sheet ABCSheet
A1: ProductCategory | B1: SKU | C1: Sum of GrossRevenue | D1: Sum of GrossRevenuePct(%) | E1: CumulativePct(%) | F1: ABCClass
A2: Accessories | B2: ACC-6626 | C2: 79082.507 | D2: 0.059386905 | E2: =SUMIF($A$2:A2, A2, $C$2:C2) / SUMIF($A$2:$A$100000, A2, $C$2:$C$100000) -> 0.059386905 | F2: =IF(E2<=0.8,"A",IF(E2<=0.95,"B","C")) -> A
A3: Accessories | B3: ACC-2988 | C3: 53034.364 | D3: 0.039826086 | E3: =SUMIF($A$2:A3, A3, $C$2:C3) / SUMIF($A$2:$A$100000, A3, $C$2:$C$100000) -> 0.09921299 | F3: =IF(E3<=0.8,"A",IF(E3<=0.95,"B","C")) -> A
A4: Accessories | B4: ACC-9283 | C4: 46450.26 | D4: 0.034881762 | E4: =SUMIF($A$2:A4, A4, $C$2:C4) / SUMIF($A$2:$A$100000, A4, $C$2:$C$100000) -> 0.13409475 | F4: =IF(E4<=0.8,"A",IF(E4<=0.95,"B","C")) -> A
A5: Accessories | B5: ACC-9533 | C5: 43084.872 | D5: 0.032354528 | E5: =SUMIF($A$2:A5, A5, $C$2:C5) / SUMIF($A$2:$A$100000, A5, $C$2:$C$100000) -> 0.16644928 | F5: =IF(E5<=0.8,"A",IF(E5<=0.95,"B","C")) -> A
A6: Accessories | B6: ACC-8098 | C6: 38096.184 | D6: 0.028608279 | E6: =SUMIF($A$2:A6, A6, $C$2:C6) / SUMIF($A$2:$A$100000, A6, $C$2:$C$100000) -> 0.19505756 | F6: =IF(E6<=0.8,"A",IF(E6<=0.95,"B","C")) -> A
A7: Accessories | B7: ACC-4490 | C7: 35396.278 | D7: 0.026580788 | E7: =SUMIF($A$2:A7, A7, $C$2:C7) / SUMIF($A$2:$A$100000, A7, $C$2:$C$100000) -> 0.22163835 | F7: =IF(E7<=0.8,"A",IF(E7<=0.95,"B","C")) -> A
A8: Accessories | B8: ACC-7838 | C8: 35167.745 | D8: 0.026409172 | E8: =SUMIF($A$2:A8, A8, $C$2:C8) / SUMIF($A$2:$A$100000, A8, $C$2:$C$100000) -> 0.24804752 | F8: =IF(E8<=0.8,"A",IF(E8<=0.95,"B","C")) -> A
A9: Accessories | B9: ACC-5177 | C9: 34139.16 | D9: 0.025636757 | E9: =SUMIF($A$2:A9, A9, $C$2:C9) / SUMIF($A$2:$A$100000, A9, $C$2:$C$100000) -> 0.27368428 | F9: =IF(E9<=0.8,"A",IF(E9<=0.95,"B","C")) -> A
A10: Accessories | B10: ACC-9162 | C10: 33062.236 | D10: 0.024828043 | E10: =SUMIF($A$2:A10, A10, $C$2:C10) / SUMIF($A$2:$A$100000, A10, $C$2:$C$100000) -> 0.29851232 | F10: =IF(E10<=0.8,"A",IF(E10<=0.95,"B","C")) -> A
A11: Accessories | B11: ACC-7078 | C11: 32086.376 | D11: 0.024095222 | E11: =SUMIF($A$2:A11, A11, $C$2:C11) / SUMIF($A$2:$A$100000, A11, $C$2:$C$100000) -> 0.32260754 | F11: =IF(E11<=0.8,"A",IF(E11<=0.95,"B","C")) -> A
A12: Accessories | B12: ACC-1375 | C12: 31513.085 | D12: 0.02366471 | E12: =SUMIF($A$2:A12, A12, $C$2:C12) / SUMIF($A$2:$A$100000, A12, $C$2:$C$100000) -> 0.34627225 | F12: =IF(E12<=0.8,"A",IF(E12<=0.95,"B","C")) -> A
A13: Accessories | B13: ACC-1659 | C13: 28386.016 | D13: 0.021316441 | E13: =SUMIF($A$2:A13, A13, $C$2:C13) / SUMIF($A$2:$A$100000, A13, $C$2:$C$100000) -> 0.36758869 | F13: =IF(E13<=0.8,"A",IF(E13<=0.95,"B","C")) -> A
... A631: Printers | B631: PRN-6276 | C631: 685.06776 | D631: 0.00042390114 | E631: =SUMIF($A$2:A631, A631, $C$2:C631) / SUMIF($A$2:$A$100000, A631, $C$2:$C$100000) -> 1 | F631: =IF(E631<=0.8,"A",IF(E631<=0.95,"B","C")) -> C

Sheet ABCPivot
A3: Row Labels | B3: Sum of Sum of GrossRevenue | C3: Count of SKU
A4: Accessories | B4: 1331648.9 | C4: 88
A5: A | B5: 1060415.8 | C5: 43
A6: B | B6: 198592.16 | C6: 22
A7: C | B7: 72640.923 | C7: 23
A8: Components | B8: 1545647 | C8: 90
A9: A | B9: 1227898.1 | C9: 39
A10: B | B10: 240397.52 | C10: 25
A11: C | B11: 77351.362 | C11: 26
A12: Laptops | B12: 1711094.4 | C12: 81
A13: A | B13: 1356084.6 | C13: 38
A14: B | B14: 267381.16 | C14: 22
A15: C | B15: 87628.653 | C15: 21
... A32: Grand Total | B32: 10928846 | C32: 630

Sheet SalespersonPivot
A3: Salesperson | B3: Orders Count | C3: Total Revenue | D3: Total Gross Profit
A4: A. Patel | B4: 46 | C4: 877159.52 | D4: 281944.47
A5: B. Chen | B5: 48 | C5: 893735.66 | D5: 315969.97
A6: C. Otieno | B6: 37 | C6: 685111.86 | D6: 225695.02
A7: D. Smith | B7: 38 | C7: 576820.19 | D7: 151076.93
A8: E. Garcia | B8: 34 | C8: 543846.44 | D8: 204981.34
A9: F. Müller | B9: 51 | C9: 812637.17 | D9: 251733.01
A10: G. Dubois | B10: 30 | C10: 510653.71 | D10: 172441.87
A11: H. Kim | B11: 45 | C11: 697568.3 | D11: 137020.81
A12: I. Johnson | B12: 38 | C12: 541165.67 | D12: 140021.69
A13: J. Njeri | B13: 50 | C13: 802384.66 | D13: 273113.11
A14: K. Singh | B14: 44 | C14: 883348.13 | D14: 278762.27
A15: L. Okafor | B15: 46 | C15: 853038.52 | D15: 269716.55
... A20: Grand Total | B20: 632 | C20: 10928846 | D20: 3401098

Sheet SalespersonProductivity
A1: Salesperson | B1: Orders Count | C1: Total Revenue | D1: Total Gross Profit | E1: Revenue per Order | F1: Gross Profit per Order | G1: Orders per Month
A2: Not Specified | B2: 8 | C2: 249026.85 | D2: 100098 | E2: =C2/B2 -> 31128.356 | F2: =D2/B2 -> 12512.25 | G2: =B2/12 -> 0.66666667
A3: M. Rossi | B3: 48 | C3: 966298.99 | D3: 302657.06 | E3: =C3/B3 -> 20131.229 | F3: =D3/B3 -> 6305.3554 | G3: =B3/12 -> 4
A4: K. Singh | B4: 44 | C4: 883348.13 | D4: 278762.27 | E4: =C4/B4 -> 20076.094 | F4: =D4/B4 -> 6335.5061 | G4: =B4/12 -> 3.6666667
A5: A. Patel | B5: 46 | C5: 877159.52 | D5: 281944.47 | E5: =C5/B5 -> 19068.685 | F5: =D5/B5 -> 6129.2276 | G5: =B5/12 -> 3.8333333
A6: B. Chen | B6: 48 | C6: 893735.66 | D6: 315969.97 | E6: =C6/B6 -> 18619.493 | F6: =D6/B6 -> 6582.7077 | G6: =B6/12 -> 4
A7: L. Okafor | B7: 46 | C7: 853038.52 | D7: 269716.55 | E7: =C7/B7 -> 18544.316 | F7: =D7/B7 -> 5863.4033 | G7: =B7/12 -> 3.8333333
A8: C. Otieno | B8: 37 | C8: 685111.86 | D8: 225695.02 | E8: =C8/B8 -> 18516.537 | F8: =D8/B8 -> 6099.8654 | G8: =B8/12 -> 3.0833333
A9: O. Wang | B9: 37 | C9: 647724.9 | D9: 185219.44 | E9: =C9/B9 -> 17506.078 | F9: =D9/B9 -> 5005.9307 | G9: =B9/12 -> 3.0833333
A10: G. Dubois | B10: 30 | C10: 510653.71 | D10: 172441.87 | E10: =C10/B10 -> 17021.79 | F10: =D10/B10 -> 5748.0624 | G10: =B10/12 -> 2.5
A11: J. Njeri | B11: 50 | C11: 802384.66 | D11: 273113.11 | E11: =C11/B11 -> 16047.693 | F11: =D11/B11 -> 5462.2622 | G11: =B11/12 -> 4.1666667
A12: E. Garcia | B12: 34 | C12: 543846.44 | D12: 204981.34 | E12: =C12/B12 -> 15995.484 | F12: =D12/B12 -> 6028.863 | G12: =B12/12 -> 2.8333333
A13: F. Müller | B13: 51 | C13: 812637.17 | D13: 251733.01 | E13: =C13/B13 -> 15934.062 | F13: =D13/B13 -> 4935.9414 | G13: =B13/12 -> 4.25
... A17: N. Brown | B17: 32 | C17: 388325.14 | D17: 110646.46 | E17: =C17/B17 -> 12135.161 | F17: =D17/B17 -> 3457.7018 | G17: =B17/12 -> 2.6666667

Sheet ChannelMixPivot
A3: Revenue Share (%) | B3: Column Labels
A4: Row Labels | B4: Direct | C4: Distributor | D4: Marketplace | E4: Not Specified | F4: Online | G4: Retail | H4: Grand Total
A5: Africa | B5: 0.1776342 | C5: 0.24017767 | D5: 0.2030569 | E5: 0.012594885 | F5: 0.16684646 | G5: 0.1996899 | H5: 1
A6: Americas | B6: 0.27964209 | C6: 0.21140873 | D6: 0.13626255 | E6: 0.0034425439 | F6: 0.25660677 | G6: 0.11263731 | H6: 1
A7: Asia | B7: 0.22609014 | C7: 0.1792799 | D7: 0.19054974 | E7: 0.014562662 | F7: 0.14558001 | G7: 0.24393754 | H7: 1
A8: Europe | B8: 0.30082759 | C8: 0.11379438 | D8: 0.20338414 | E8: 0.0064443142 | F8: 0.20900009 | G8: 0.16654949 | H8: 1
A9: Grand Total | B9: 0.24690255 | C9: 0.18487541 | D9: 0.18345598 | E9: 0.0092784644 | F9: 0.19420404 | G9: 0.18128356 | H9: 1

Sheet ServiceLevelPivot
A3: Row Labels | B3: Orders Met 7-Day Target | C3: % Orders Met 7-Day Target
A4: Brazil | B4: 18 | C4: 0.29032258
A5: Accessories | B5: 4 | C5: 0.4
A6: Components | B6: 1 | C6: 0.14285714
A7: Laptops | B7: 1 | C7: 0.2
A8: Monitors | B8: 3 | C8: 0.25
A9: Networking | B9: 2 | C9: 0.16666667
A10: Phones | B10: 5 | C10: 0.55555556
A11: Printers | B11: 2 | C11: 0.28571429
A12: Canada | B12: 9 | C12: 0.20454545
A13: Accessories | B13: 2 | C13: 0.33333333
A14: Components | B14: 3 | C14: 0.5
A15: Laptops | B15: 2 | C15: 0.33333333
... A100: Grand Total | B100: 172 | C100: 0.2721519

Sheet PriceCompliancePivot
A3: Row Labels | B3: Orders with Discount > 20% | C3: Share of High-Discount Orders (%)
A4: Africa | B4: 22 | C4: 0.22943038
A5: A. Patel | B5: 3 | C5: 0.11034483
A6: B. Chen | B6: 0 | C6: 0.055172414
A7: C. Otieno | B7: 2 | C7: 0.055172414
A8: D. Smith | B8: 2 | C8: 0.068965517
A9: E. Garcia | B9: 1 | C9: 0.034482759
A10: F. Müller | B10: 0 | C10: 0.089655172
A11: G. Dubois | B11: 0 | C11: 0.020689655
A12: H. Kim | B12: 1 | C12: 0.048275862
A13: I. Johnson | B13: 2 | C13: 0.055172414
A14: J. Njeri | B14: 3 | C14: 0.082758621
A15: K. Singh | B15: 0 | C15: 0.096551724
... A71: O. Wang | B71: 0 | C71: 0.050314465
A72: (blank) | C72: 0
A73: (blank)
A74: Grand Total | B74: 90 | C74: 1

Sheet WhatIf_Panel
A2: Global Discount Cap (0%–25%) | B2: 0.25
A3: UnitCost Inflation (0%–15%) | B3: 0.1
A4: Quantity Uplift (0%–20%) | B4: 0.05
A5: A | B5: B | C5: C | D5: D
A6: Metric | B6: Baseline | C6: Scenario | D6: Delta
A7: Total GrossRevenue | B7: =SUM(Excel_Assignment!U:U) -> 10928846 | C7: =SUM(Excel_Assignment!AM:AM) -> 11507685 | D7: =C7-B7 -> 578839.62
A8: Total GrossProfit | B8: =SUM(Excel_Assignment!W:W) -> 3401098 | C8: =SUM(Excel_Assignment!AO:AO) -> 2813449.9 | D8: =C8-B8 -> -587648.09
A9: Avg MarginPct | B9: =AVERAGE(Excel_Assignment!X:X) -> -0.27279049 | C9: =AVERAGE(Excel_Assignment!AP:AP) -> -0.39761825 | D9: =C9-B9 -> -0.12482776

Sheet Discount_Outliers_Data
A1: DiscountPct | B1: Region
A2: 0.112 | B2: Africa
A3: 0.237 | B3: Africa
A4: 0.131 | B4: Africa
A5: 0.072 | B5: Africa
A6: 0.102 | B6: Asia
A7: 0 | B7: Americas
A8: 0.147 | B8: Asia
A9: 0.194 | B9: Africa
A10: 0.031 | B10: Africa
A11: 0.149 | B11: Americas
A12: 0.006 | B12: Europe
A13: 0.25 | B13: Asia
... A633: 0.173 | B633: Asia

Sheet Dashboard_Pivots
A3: Month | B3: Sum of GrossRevenue | D3: Sum of GrossProfit | E3: Column Labels | M3: Row Labels | N3: Average of DiscountPct(%) | O3: Region | P3: DiscountPct
A4: Apr-2023 | B4: 371604.58 | D4: Row Labels | E4: Direct | F4: Distributor | G4: Marketplace | H4: Not Specified | I4: Online | J4: Retail | K4: Grand Total | M4: Africa | N4: 0.11954483 | O4: Africa | P4: =IFERROR(GETPIVOTDATA("Average of DiscountPct(%)",$N$4,"Region",O4),"") -> 0.11954483
A5: Apr-2024 | B5: 239506.83 | D5: Africa | E5: 177919.82 | F5: 192042.35 | G5: 164839.3 | H5: 16237.344 | I5: 145453.95 | J5: 141171.08 | K5: 837663.85 | M5: Americas | N5: 0.12364968 | O5: Americas | P5: =IFERROR(GETPIVOTDATA("Average of DiscountPct(%)",$N$4,"Region",O5),"") -> 0.12364968
A6: Apr-2025 | B6: 336135.17 | D6: Americas | E6: 258674.93 | F6: 175298.68 | G6: 96609.648 | H6: 777.96 | I6: 261943.84 | J6: 69035.709 | K6: 862340.77 | M6: Asia | N6: 0.12683626 | O6: Asia | P6: =IFERROR(GETPIVOTDATA("Average of DiscountPct(%)",$N$4,"Region",O6),"") -> 0.12683626
A7: Aug-2023 | B7: 339044.67 | D7: Asia | E7: 229217.48 | F7: 151146.75 | G7: 128045.01 | H7: 20547.545 | I7: 149042.39 | J7: 153258.56 | K7: 831257.73 | M7: Europe | N7: 0.11483019 | O7: Europe | P7: =IFERROR(GETPIVOTDATA("Average of DiscountPct(%)",$N$4,"Region",O7),"") -> 0.11483019
A8: Aug-2024 | B8: 383755.42 | D8: Europe | E8: 292716.95 | F8: 105550.85 | G8: 111692.81 | H8: 8028.7065 | I8: 200067.16 | J8: 151779.17 | K8: 869835.66 | M8: Grand Total | N8: 0.12135127 | P8: =IFERROR(GETPIVOTDATA("Average of DiscountPct(%)",$N$4,"Region",O8),"")
A9: Aug-2025 | B9: 366808.72 | D9: Grand Total | E9: 958529.18 | F9: 624038.63 | G9: 501186.77 | H9: 45591.556 | I9: 756507.34 | J9: 515244.53 | K9: 3401098
A10: Dec-2023 | B10: 382101.37
A11: Dec-2024 | B11: 354378.94 | D11: Row Labels | E11: Sum of GrossRevenue
A12: Feb-2023 | B12: 433788.64 | D12: CMP-8851 | E12: 139277.83
A13: Feb-2024 | B13: 307793.71 | D13: NET-2365 | E13: 109244
A14: Feb-2025 | B14: 221608.5 | D14: LAP-8910 | E14: 102122.94
A15: Jan-2023 | B15: 178642.74 | D15: MON-6962 | E15: 92715.25
A16: Jan-2024 | B16: 299100.37 | D16: MON-2266 | E16: 87404.93
A17: Jan-2025 | B17: 223498.2 | D17: MON-6699 | E17: 85637.74
A18: Jul-2023 | B18: 550462.85 | D18: CMP-3938 | E18: 84136.12
A19: Jul-2024 | B19: 275628.62 | D19: LAP-3904 | E19: 82514.712
A20: Jul-2025 | B20: 486970.83 | D20: NET-5987 | E20: 82141.34
A21: Jun-2023 | B21: 236474.06 | D21: NET-5523 | E21: 79548.756
A22: Jun-2024 | B22: 634490.72 | D22: Grand Total | E22: 944743.62
A23: Jun-2025 | B23: 382009.38
A24: Mar-2023 | B24: 215576.67
A25: Mar-2024 | B25: 374300.11
A26: Mar-2025 | B26: 209101.52
A27: May-2023 | B27: 469902.37
A28: May-2024 | B28: 416985.77
A29: May-2025 | B29: 375285.78
A30: Nov-2023 | B30: 127009.51
A31: Nov-2024 | B31: 416944.19
A32: Oct-2023 | B32: 241851.11
A33: Oct-2024 | B33: 416924.95
A34: Sep-2023 | B34: 141266.51
... A37: Grand Total | B37: 10928846
A39: Sum of GrossRevenue
A40: 10928846
A42: Sum of GrossProfit
A43: 3401098
A45: Sum of MarginPct(%)
A46: -172.40359
A48: Average of GrossRevenue
...

Sheet Dashboard
